Workbook

Sheet category
A1: id | B1: name | C1: category_id
A2: 1 | B2: STAINLESS PIANO HINGES WITH SCREW | C2: 1
A3: 2 | B3: PVC COATED CUP HOOK | C3: 2
A4: 3 | B4: B/P CUP HOOK (BRASS) | C4: 3
A5: 4 | B5: MAGNETIC DOOR STOPPER | C5: 4
A6: 5 | B6: DRAWER LOCK | C6: 5
A7: 6 | B7: BAG-PLATED RED COPPER CABINET DRAWER HANDLES (NEW ARRIVAL) | C7: 6
A8: 7 | B8: BAG-PLATED BRONZE CABINET DRAWER HANDLES (NEW ARRIVAL) | C8: 7
A9: 8 | B9: SOLID DOOR | C9: 8
A10: 9 | B10: T-TYPE STAINLESS HANDLE LIGHT DUTY | C10: 9
A11: 10 | B11: T-TYPE STAINLESS HANDLE HEAVY DUTY | C11: 10
A12: 11 | B12: STAINLESS BOLT W/ STAINLESS SCREW | C12: 11
A13: 12 | B13: STAINLESS BARREL BOLTS WITH HASP | C13: 12
... A334: 333 | B334: EXTRA THICK HOSE | C334: 333

Sheet unit
A1: id | B1: name | C1: unit_id
A2: 1 | B2: pc | C2: 1
A3: 2 | B3: set | C3: 2
A4: 3 | B4: roll | C4: 3
A5: 4 | B5: pcs/ctn | C5: 4
A6: 5 | B6: pcs/bag | C6: 5
A7: 6 | B7: boxes/ctn | C7: 6
A8: 7 | B8: pcs/sack | C8: 7
A9: 8 | B9: doz | C9: 8
A10: 9 | B10: pair | C10: 9
A11: 10 | B11: pack | C11: 10
A12: 11 | B12: ctn | C12: 11
A13: 12 | B13: box | C13: 12
... A17: 16 | B17: pc/ctn | C17: 16

Sheet SUPPLIERS
A1: supplier_code | B1: name | C1: mobile | D1: address | E1: details | F1: tax | G1: email | H1: previous_balance | I1: status
A2: 1ST-194 | B2: 1ST TOOLS TRADING INC. | I2: 1
A3: AIM-229 | B3: AIMATCO BUILDERS SUPPLY INC. | C3: 8364-41-37 | D3: 58 E. FERNANDEZ ST. BATIS 1500 CITY OF SAN JUAN NCR | E3: 8364-41-37 / 8361-41-57 / 8364-22-70 / 8364-43-54 / 8364-41-59 | F3: 606-012-675-00002 | I3: 1
A4: ALA-683 | B4: ALASCO VINYL CORPORATION | C4: 0917-803-3905 | D4: 665 7TH AVENUE BRGY. 121 GRACE PARK ZONE 11 1400 CALOOCAN CITY | E4: (632) 8292.222 / (632) 8291.1415 / 0917-803-3905 / 0922-842-6371 / 0999-888-6371 | F4: 000-302-886-00000 | I4: 1
A5: AMA-932 | B5: AMAZON MANUFACTURING CORPORATION | C5: 8983-7519 | D5: 109 PASOLO ROAD, PASOLO, VALENZUELA CITY | E5: 8983-7519 /3440-6042 / 3456-8150 / 0922-880-9595 / 0917-626-3288 | F5: 000-240-178-00000 | I5: 1
A6: DRE-779 | B6: DREAM DOOR PHILS. ENTERPRISES | C6: 8716-2112 | D6: 4 TRINIDAD ST. DIST. 1 1447, VALENZUELA CITY | E6: 8716-2112 / 0932-716-5396 | F6: 103-961-945-00004 | I6: 1
A7: ERE-562 | B7: EREANTIC CORPORATION | D7: 978 ALIW-IW ST. MORNINGSIDE TERRACE SUBD. STA. MESA, MANILA | I7: 1
A8: JER-890 | B8: JERICSON MARKETING | C8: 0917-878-7987 | D8: BANCAL, FVIC, MEYCAUAYAN CITY | E8: 0917-878-7987 | I8: 1
A9: LIT-749 | B9: LITELUX MARKETING | C9: 0966-629-1657 | E9: 0966-629-1657 | I9: 1
A10: PNM-208 | B10: PNM MARKETING COMPANY | C10: 6461182 | D10: 11 ATIMOYA ST., POTRERO MALABON | E10: (632) 6461182 | I10: 1
A11: POL-650 | B11: POLYLINE INDUSTRIES CORPORATED | D11: 107 F. MARIANO AVE. BRGY. DE LA PAZ, PASIG CITY | F11: 000-285-920-000 | I11: 1
A12: QP-865 | B12: QP INDUSTRIAL CORPORATTION | D12: 93 PARADA ROAD, MAYSAN, VALENZUELA CITY | F12: 003-509-622-000 | I12: 1
A13: SAN-919 | B13: SANTECH INDUSTRIAL CORPORATION | C13: 8293-3238 | E13: 8293-9523 / 8292-8373 / 8293-3238 / 8291-3731 / 8292-7652 | I13: 1
A14: STE-984 | B14: STEELWORLD MANUFACTURING CORPORATION | D14: 16 INDUSTRIAL ROAD BRGY. KARUHATAN DIST. 2, 1441 VALENZUELA CITY NCR | F14: 000-297-245-00000 | I14: 1
A15: STR-308 | B15: STRAIGHTDEAL MARKETING INC. | D15: NO. 35 SAPOCOY STREET MANRESA 1115 QUEZON CITY | F15: 609-297-357-00000 | I15: 1
A16: TIG-351 | B16: TIGER INDUSTRIES | C16: 0961-500-6091 | D16: CALOOCAN CITY | E16: 0961-500-6091 / 0995-772-2378 | I16: 1
A17: VOR-931 | B17: VORSC WIRES AND CABLES CORPORATION | I17: 1
A18: WIN-505 | B18: WINWAY/HAPPY DAY TRADING | C18: 02-82776885 | E18: 02-82774174 / 02-82776885 | I18: 1
A19: ZYT-591 | B19: ZYTEC TRADING | D19: NO. 23 5TH STREET, 6TH AVENUE, CALOOCAN CITY | I19: 1
A20: COC-556 | B20: COCO COUNTRY ENTERPRISE | C20: 8-363-7865 | D20: PUROK 4, DULONG BARRIO, B O S INDUSTRIAL COMP., MATUNGAO, BULACAN, BULACAN | E20: 8-363-7865 | F20: 217-137-592-00000 | I20: 1
A21: IND-852 | B21: INDUSTRIAL WELDING CORPORATION | C21: 8789-1000 | D21: 17 MC ARTHUR HI-WAY BRGY. POTRERO, DISTRICT II, MALABON CITY | E21: 8789-1000 | F21: 000-236-850-001 | I21: 1
A22: FIR-451 | B22: FIREFLY ELECTRIC & LIGHTING CORPORATION | D22: 55 T. SANTIAGO COR. P. GREGORIO ST. LINGUNAN 1446 VALENZUELA CITY | F22: 210-714-705-00000 | I22: 1
A23: DEV-105 | B23: DEVELOPMENT TRADING WHOLESALER & DISTRIBUTOR OF ELECTRICAL SUPPLY | C23: 02-898-41380 | D23: LAWA, MALHACAN, MEYCAUAYAN, BULACAN | E23: 02-899-84992 / 02-898-41380 | F23: 108-996-008-000 | I23: 1
A24: MAR-525 | B24: MARCH RESOURCES MANUFACTURING CORPORATION | C24: 8241-8428 | D24: #90 RUBBER MASTER ROAD, LINGUNAN, VALENZUELA CITY | E24: 8241-8428 / 8243-1415 / 8242-4351 / 8242-5443 | F24: 002-033-338-00000 | I24: 1
A25: MAR-452 | B25: MARSWIN MARKETING INC. | C25: 355 7777 | D25: 408 SAN NICOLAS ST., BINONDO, MANILA | E25: (63-2) 355 7777 | I25: 1
A26: TOM-310 | B26: TOMITA INDUSTRIAL & MACHINERY, INC. | C26: 8288-38-98 | D26: 5TH FLOOR TOYOMA GROUP CENTER, #22 TIMOG AVE. LAGING HANDA, QUEZON CITY | E26: 8288-38-98 / 8288-97-90 / 8287-45-27 / 0932-857-9888 / 0927-529-8842 | F26: 209-659-388-0000 | I26: 1
A27: SUN-136 | B27: SUNVIEW ENTERPRISES | I27: 1

Sheet SUPPLIER_ITEMS (1st Tools)
A1: supplier_id | B1: category | C1: item_description | D1: item_code | E1: item_price | F1: item price | G1: unit | H1: volume_less | I1: regular_less
A2: 1ST TOOLS TRADING INC. | B2: STAINLESS STRAINER | C2: PL22050-1 STAINLESS BASKET STRAINER 2-1/2 DUPLEX STRAINER | D2: 1ST-358-001 | E2: 52/PC | F2: =VALUE(LEFT(E2,FIND("/",E2)-1)) -> 52 | G2: =TRIM(MID(E2,FIND("/",E2)+1,LEN(E2))) -> PC | H2: ASSTD ORDER 10 CTN + 1 CTN FREE | I2: Net
A3: 1ST TOOLS TRADING INC. | B3: STAINLESS STRAINER | C3: PL22050-2 (LTSN011) STAINLESS BASKET STRAINER 4- 1/2 | D3: =LEFT($D$2,FIND("-",$D$2,FIND("-",$D$2)+1)) & TEXT(RIGHT($D$2,3)+ROW(D1),"000") -> 1ST-358-002 | E3: 90/PC | F3: =VALUE(LEFT(E3,FIND("/",E3)-1)) -> 90 | G3: =TRIM(MID(E3,FIND("/",E3)+1,LEN(E3))) -> PC | H3: ASSTD ORDER 10 CTN + 1 CTN FREE | I3: Net
A4: 1ST TOOLS TRADING INC. | B4: STAINLESS STRAINER | C4: PL22150-1 4"*4" POLONET STRAINER | D4: =LEFT($D$2,FIND("-",$D$2,FIND("-",$D$2)+1)) & TEXT(RIGHT($D$2,3)+ROW(D2),"000") -> 1ST-358-003 | E4: 14/PC | F4: =VALUE(LEFT(E4,FIND("/",E4)-1)) -> 14 | G4: =TRIM(MID(E4,FIND("/",E4)+1,LEN(E4))) -> PC | H4: 13/PC ASSTD ORDER 10CTN | I4: Net
A5: 1ST TOOLS TRADING INC. | B5: STAINLESS STRAINER | C5: PL22150-2 4''*4 POLONET STAINLESS STRAINER | D5: =LEFT($D$2,FIND("-",$D$2,FIND("-",$D$2)+1)) & TEXT(RIGHT($D$2,3)+ROW(D3),"000") -> 1ST-358-004 | E5: 28/PC | F5: =VALUE(LEFT(E5,FIND("/",E5)-1)) -> 28 | G5: =TRIM(MID(E5,FIND("/",E5)+1,LEN(E5))) -> PC | H5: 27/PC ASSTD ORDER 10/CTN | I5: Net
A6: 1ST TOOLS TRADING INC. | B6: HI-GRADE STAINLESS FLOOR STRAINER | C6: PL22151-1 HI-GRADE STAINLESS FLOOR STRAINER 4"*4" | D6: =LEFT($D$2,FIND("-",$D$2,FIND("-",$D$2)+1)) & TEXT(RIGHT($D$2,3)+ROW(D4),"000") -> 1ST-358-005 | E6: 82/PC | F6: =VALUE(LEFT(E6,FIND("/",E6)-1)) -> 82 | G6: =TRIM(MID(E6,FIND("/",E6)+1,LEN(E6))) -> PC | H6: 75/PC ASSTD ORDER 5CTN | I6: Net
A7: 1ST TOOLS TRADING INC. | B7: HI-GRADE STAINLESS FLOOR STRAINER | C7: PL22151-2 HI-GRADE STAINLESS FLOOR STRAINER 6"*6" | D7: =LEFT($D$2,FIND("-",$D$2,FIND("-",$D$2)+1)) & TEXT(RIGHT($D$2,3)+ROW(D5),"000") -> 1ST-358-006 | E7: 168/PC | F7: =VALUE(LEFT(E7,FIND("/",E7)-1)) -> 168 | G7: =TRIM(MID(E7,FIND("/",E7)+1,LEN(E7))) -> PC | H7: 152/PC ASSTD ORDER 5CTN | I7: Net
A8: 1ST TOOLS TRADING INC. | B8: KITCHEN SINK | C8: PL22040-00 STAINLESS KITCHEN SINK 15"*20 | D8: =LEFT($D$2,FIND("-",$D$2,FIND("-",$D$2)+1)) & TEXT(RIGHT($D$2,3)+ROW(D6),"000") -> 1ST-358-007 | E8: 168/PC | F8: =VALUE(LEFT(E8,FIND("/",E8)-1)) -> 168 | G8: =TRIM(MID(E8,FIND("/",E8)+1,LEN(E8))) -> PC | H8: Net | I8: Net
A9: 1ST TOOLS TRADING INC. | B9: KITCHEN SINK | C9: PL22040-01 STAINLESS KITCHEN SINK 16"*24" | D9: =LEFT($D$2,FIND("-",$D$2,FIND("-",$D$2)+1)) & TEXT(RIGHT($D$2,3)+ROW(D7),"000") -> 1ST-358-008 | E9: 180/PC | F9: =VALUE(LEFT(E9,FIND("/",E9)-1)) -> 180 | G9: =TRIM(MID(E9,FIND("/",E9)+1,LEN(E9))) -> PC | H9: Net | I9: Net
A10: 1ST TOOLS TRADING INC. | B10: KITCHEN SINK | C10: PL22041-00 21"*17"*6.5 PLAIN STAINLESS KITCHEN SINK | D10: =LEFT($D$2,FIND("-",$D$2,FIND("-",$D$2)+1)) & TEXT(RIGHT($D$2,3)+ROW(D8),"000") -> 1ST-358-009 | E10: 275/PC | F10: =VALUE(LEFT(E10,FIND("/",E10)-1)) -> 275 | G10: =TRIM(MID(E10,FIND("/",E10)+1,LEN(E10))) -> PC | H10: 250/PC ASSTD ORDER ALL SINK 10CTN | I10: Net
A11: 1ST TOOLS TRADING INC. | B11: KITCHEN SINK | C11: PL22041-01 30"*16"*5"RIGHT DRAIN STAINLESS KITCHEN SINK | D11: =LEFT($D$2,FIND("-",$D$2,FIND("-",$D$2)+1)) & TEXT(RIGHT($D$2,3)+ROW(D9),"000") -> 1ST-358-010 | E11: 345/PC | F11: =VALUE(LEFT(E11,FIND("/",E11)-1)) -> 345 | G11: =TRIM(MID(E11,FIND("/",E11)+1,LEN(E11))) -> PC | H11: 320/PC ASSTD ORDER ALL SINK 10CTN | I11: Net
A12: 1ST TOOLS TRADING INC. | B12: KITCHEN SINK | C12: PL22041-02 30"*16"*5"-LEFT DRAIN STAINLESS KITCHEN SINK | D12: =LEFT($D$2,FIND("-",$D$2,FIND("-",$D$2)+1)) & TEXT(RIGHT($D$2,3)+ROW(D10),"000") -> 1ST-358-011 | E12: 345/PC | F12: =VALUE(LEFT(E12,FIND("/",E12)-1)) -> 345 | G12: =TRIM(MID(E12,FIND("/",E12)+1,LEN(E12))) -> PC | I12: Net
A13: 1ST TOOLS TRADING INC. | B13: KITCHEN SINK | C13: PL22041-03 30"*18"*7" RIGHT DRAIN STAINLESS KITCHEN SINK | D13: =LEFT($D$2,FIND("-",$D$2,FIND("-",$D$2)+1)) & TEXT(RIGHT($D$2,3)+ROW(D11),"000") -> 1ST-358-012 | E13: 515/PC | F13: =VALUE(LEFT(E13,FIND("/",E13)-1)) -> 515 | G13: =TRIM(MID(E13,FIND("/",E13)+1,LEN(E13))) -> PC | H13: 490/PC ASSTD ORDER ALL SINK 10CTN | I13: Net
A14: 1ST TOOLS TRADING INC. | B14: KITCHEN SINK | C14: PL22041-04 30"*18"*7"-LEFT DRAIN STAINLESS KITCHEN SINK | D14: =LEFT($D$2,FIND("-",$D$2,FIND("-",$D$2)+1)) & TEXT(RIGHT($D$2,3)+ROW(D12),"000") -> 1ST-358-013 | E14: 515/PC | F14: =VALUE(LEFT(E14,FIND("/",E14)-1)) -> 515 | G14: =TRIM(MID(E14,FIND("/",E14)+1,LEN(E14))) -> PC | I14: Net
A15: 1ST TOOLS TRADING INC. | B15: KITCHEN SINK | C15: PL22041-05 31"*17"*6.5" DOUBLE BOWL STAINLESS KITCHEN SINK | D15: =LEFT($D$2,FIND("-",$D$2,FIND("-",$D$2)+1)) & TEXT(RIGHT($D$2,3)+ROW(D13),"000") -> 1ST-358-014 | E15: 615/PC | F15: =VALUE(LEFT(E15,FIND("/",E15)-1)) -> 615 | G15: =TRIM(MID(E15,FIND("/",E15)+1,LEN(E15))) -> PC | H15: 600/PC ASSTD ORDER ALL SINK 10CTN | I15: Net
A16: 1ST TOOLS TRADING INC. | B16: KITCHEN SINK | C16: PL22041-06 40"*20"*6" RIGHT DRAIN STAINLESS KITCHEN SINK | D16: =LEFT($D$2,FIND("-",$D$2,FIND("-",$D$2)+1)) & TEXT(RIGHT($D$2,3)+ROW(D14),"000") -> 1ST-358-015 | E16: 555/PC | F16: =VALUE(LEFT(E16,FIND("/",E16)-1)) -> 555 | G16: =TRIM(MID(E16,FIND("/",E16)+1,LEN(E16))) -> PC | H16: 500/PC ASSTD ORDER ALL SINK 10CTN | I16: Net
A17: 1ST TOOLS TRADING INC. | B17: KITCHEN SINK | C17: PL22041-07 40"*20"*6"-LEFT DRAIN STAINLESS KITCHEN SINK | D17: =LEFT($D$2,FIND("-",$D$2,FIND("-",$D$2)+1)) & TEXT(RIGHT($D$2,3)+ROW(D15),"000") -> 1ST-358-016 | E17: 555/PC | F17: =VALUE(LEFT(E17,FIND("/",E17)-1)) -> 555 | G17: =TRIM(MID(E17,FIND("/",E17)+1,LEN(E17))) -> PC | I17: Net
A18: 1ST TOOLS TRADING INC. | B18: KITCHEN SINK | C18: PL22041-08 POLONET STAINLESS KITCHEN SINK 15"*15"*6 | D18: =LEFT($D$2,FIND("-",$D$2,FIND("-",$D$2)+1)) & TEXT(RIGHT($D$2,3)+ROW(D16),"000") -> 1ST-358-017 | E18: 205/PC | F18: =VALUE(LEFT(E18,FIND("/",E18)-1)) -> 205 | G18: =TRIM(MID(E18,FIND("/",E18)+1,LEN(E18))) -> PC | H18: 205/PC ASSTD ORDER ALL SINK 10CTN | I18: Net
A19: 1ST TOOLS TRADING INC. | B19: KITCHEN SINK | C19: PL22041-09 19"*19"*6.5" STAINLESS KITCHEN SINK | D19: =LEFT($D$2,FIND("-",$D$2,FIND("-",$D$2)+1)) & TEXT(RIGHT($D$2,3)+ROW(D17),"000") -> 1ST-358-018 | E19: 345/PC | F19: =VALUE(LEFT(E19,FIND("/",E19)-1)) -> 345 | G19: =TRIM(MID(E19,FIND("/",E19)+1,LEN(E19))) -> PC | H19: 320/PC ASSTD ORDER ALL SINK 10CTN | I19: Net
A20: 1ST TOOLS TRADING INC. | B20: KITCHEN SINK | C20: PL22041-10 48"*20"*7.5"-DOUBLE BOWL RIGHT DRAIN STAINLESS KITCHEN SINK | D20: =LEFT($D$2,FIND("-",$D$2,FIND("-",$D$2)+1)) & TEXT(RIGHT($D$2,3)+ROW(D18),"000") -> 1ST-358-019 | E20: 1055/PC | F20: =VALUE(LEFT(E20,FIND("/",E20)-1)) -> 1055 | G20: =TRIM(MID(E20,FIND("/",E20)+1,LEN(E20))) -> PC | H20: 990/PC ASSTD ORDER ALL SINK 10CTN | I20: Net
A21: 1ST TOOLS TRADING INC. | B21: KITCHEN SINK | C21: PL22041-11 48"*20"*7.5"-DOUBLE BOWL LEFT DRAIN STAINLESS KITCHEN SINK | D21: =LEFT($D$2,FIND("-",$D$2,FIND("-",$D$2)+1)) & TEXT(RIGHT($D$2,3)+ROW(D19),"000") -> 1ST-358-020 | E21: 1055/PC | F21: =VALUE(LEFT(E21,FIND("/",E21)-1)) -> 1055 | G21: =TRIM(MID(E21,FIND("/",E21)+1,LEN(E21))) -> PC | H21: 990/PC ASSTD ORDER ALL SINK 10CTN | I21: Net
A22: 1ST TOOLS TRADING INC. | B22: KITCHEN SINK | C22: PL22042-01 22"*18"*8.5" SINGLE STAINLESS STEEL HAND SINK SATIN | D22: =LEFT($D$2,FIND("-",$D$2,FIND("-",$D$2)+1)) & TEXT(RIGHT($D$2,3)+ROW(D20),"000") -> 1ST-358-021 | E22: 1250/PC | F22: =VALUE(LEFT(E22,FIND("/",E22)-1)) -> 1250 | G22: =TRIM(MID(E22,FIND("/",E22)+1,LEN(E22))) -> PC | H22: 1200/PC ASSTD ORDER ALL SINK 10CTN | I22: Net
A23: 1ST TOOLS TRADING INC. | B23: KITCHEN SINK | C23: PL22042-02 22"*18"*8.5" SINGLE SINK STAINLESS STEEL HAND SINK BLACK | D23: =LEFT($D$2,FIND("-",$D$2,FIND("-",$D$2)+1)) & TEXT(RIGHT($D$2,3)+ROW(D21),"000") -> 1ST-358-022 | E23: 1550/PC | F23: =VALUE(LEFT(E23,FIND("/",E23)-1)) -> 1550 | G23: =TRIM(MID(E23,FIND("/",E23)+1,LEN(E23))) -> PC | H23: 1485/PC ASSTD ORDER ALL SINK 10CTN | I23: Net
A24: 1ST TOOLS TRADING INC. | B24: KITCHEN SINK | C24: PL22042-03 24"*18"*8.5" SINGLE SINK STAINLESS STEEL HAND SINK SATIN | D24: =LEFT($D$2,FIND("-",$D$2,FIND("-",$D$2)+1)) & TEXT(RIGHT($D$2,3)+ROW(D22),"000") -> 1ST-358-023 | E24: 1350/PC | F24: =VALUE(LEFT(E24,FIND("/",E24)-1)) -> 1350 | G24: =TRIM(MID(E24,FIND("/",E24)+1,LEN(E24))) -> PC | H24: 1275/PC ASSTD ORDER ALL SINK 10CTN | I24: Net
A25: 1ST TOOLS TRADING INC. | B25: KITCHEN SINK | C25: PL22042-04 24"*18"*8.5" SINGLE SINK STAINLESS STEEL HAND SINK BLACK | D25: =LEFT($D$2,FIND("-",$D$2,FIND("-",$D$2)+1)) & TEXT(RIGHT($D$2,3)+ROW(D23),"000") -> 1ST-358-024 | E25: 1650/PC | F25: =VALUE(LEFT(E25,FIND("/",E25)-1)) -> 1650 | G25: =TRIM(MID(E25,FIND("/",E25)+1,LEN(E25))) -> PC | H25: 1560/PC ASSTD ORDER ALL SINK 10CTN | I25: Net
A26: 1ST TOOLS TRADING INC. | B26: KITCHEN SINK | C26: PL22042-05 26"*18"*8.5" SINGLE SINK STAINLESS STEEL HAND SINK SATIN | D26: =LEFT($D$2,FIND("-",$D$2,FIND("-",$D$2)+1)) & TEXT(RIGHT($D$2,3)+ROW(D24),"000") -> 1ST-358-025 | E26: 1385/PC | F26: =VALUE(LEFT(E26,FIND("/",E26)-1)) -> 1385 | G26: =TRIM(MID(E26,FIND("/",E26)+1,LEN(E26))) -> PC | H26: 1300/PC ASSTD ORDER ALL SINK 10CTN | I26: Net
A27: 1ST TOOLS TRADING INC. | B27: KITCHEN SINK | C27: PL22042-06 26"*18"*8.5" SINGLE SINK STAINLESS STEEL HAND SINK BLACK | D27: =LEFT($D$2,FIND("-",$D$2,FIND("-",$D$2)+1)) & TEXT(RIGHT($D$2,3)+ROW(D25),"000") -> 1ST-358-026 | E27: 1685/PC | F27: =VALUE(LEFT(E27,FIND("/",E27)-1)) -> 1685 | G27: =TRIM(MID(E27,FIND("/",E27)+1,LEN(E27))) -> PC | H27: 1600/PC ASSTD ORDER ALL SINK 10CTN | I27: Net
A28: 1ST TOOLS TRADING INC. | B28: KITCHEN SINK | C28: PL22042-07 31"*17"*8.5" DOUBLE SINK STAINLESS STEEL HAND SINK SATIN | D28: =LEFT($D$2,FIND("-",$D$2,FIND("-",$D$2)+1)) & TEXT(RIGHT($D$2,3)+ROW(D26),"000") -> 1ST-358-027 | E28: 1750/PC | F28: =VALUE(LEFT(E28,FIND("/",E28)-1)) -> 1750 | G28: =TRIM(MID(E28,FIND("/",E28)+1,LEN(E28))) -> PC | H28: 1670/PC ASSTD ORDER ALL SINK 10CTN | I28: Net
A29: 1ST TOOLS TRADING INC. | B29: KITCHEN SINK | C29: PL22042-08 31"*17"*8.5" DOUBLE SINK STAINLESS STEEL HAND SINK BLACK | D29: =LEFT($D$2,FIND("-",$D$2,FIND("-",$D$2)+1)) & TEXT(RIGHT($D$2,3)+ROW(D27),"000") -> 1ST-358-028 | E29: 2150/PC | F29: =VALUE(LEFT(E29,FIND("/",E29)-1)) -> 2150 | G29: =TRIM(MID(E29,FIND("/",E29)+1,LEN(E29))) -> PC | H29: 2000/PC ASSTD ORDER ALL SINK 10CTN | I29: Net
... A34: 1ST TOOLS TRADING INC. | B34: KITCHEN SINK | C34: PL22043-1 304 STAINLESS STEEL KITCHEN SINK 32"*18"*8"82"*45*20CM | D34: =LEFT($D$2,FIND("-",$D$2,FIND("-",$D$2)+1)) & TEXT(RIGHT($D$2,3)+ROW(D32),"000") -> 1ST-358-033 | E34: 4000/SET | F34: =VALUE(LEFT(E34,FIND("/",E34)-1)) -> 4000 | G34: =TRIM(MID(E34,FIND("/",E34)+1,LEN(E34))) -> SET | H34: 3600/SET ASSTD ORDER 5 CTN | I34: Net
A35: 1ST TOOLS TRADING INC. | B35: GARDEN HOSE | C35: PL22090-1 (LT22014-G1) GARDEN HOSE GREEN 1/2"*90M | D35: =LEFT($D$2,FIND("-",$D$2,FIND("-",$D$2)+1)) & TEXT(RIGHT($D$2,3)+ROW(D33),"000") -> 1ST-358-034 | E35: 800/ROLL | F35: =VALUE(LEFT(E35,FIND("/",E35)-1)) -> 800 | G35: =TRIM(MID(E35,FIND("/",E35)+1,LEN(E35))) -> ROLL | I35: Net
A36: 1ST TOOLS TRADING INC. | B36: GARDEN HOSE | C36: PL22090-2 (LT22014-G2) GARDEN HOSE GREEN 5/8"*90M | D36: =LEFT($D$2,FIND("-",$D$2,FIND("-",$D$2)+1)) & TEXT(RIGHT($D$2,3)+ROW(D34),"000") -> 1ST-358-035 | E36: 930/ROLL | F36: =VALUE(LEFT(E36,FIND("/",E36)-1)) -> 930 | G36: =TRIM(MID(E36,FIND("/",E36)+1,LEN(E36))) -> ROLL | I36: Net
A37: 1ST TOOLS TRADING INC. | B37: GARDEN HOSE | C37: PL22090-3 (LT22014-G3)GARDEN HOSE GREEN 3/4"*60M | D37: =LEFT($D$2,FIND("-",$D$2,FIND("-",$D$2)+1)) & TEXT(RIGHT($D$2,3)+ROW(D35),"000") -> 1ST-358-036 | E37: 1030/ROLL | F37: =VALUE(LEFT(E37,FIND("/",E37)-1)) -> 1030 | G37: =TRIM(MID(E37,FIND("/",E37)+1,LEN(E37))) -> ROLL | H37: ASSTD ORDER | I37: Net
A38: 1ST TOOLS TRADING INC. | B38: GARDEN HOSE | C38: PL22090-4 (LT22014-G4) GARDEN HOSE GREEN 1"*60M | D38: =LEFT($D$2,FIND("-",$D$2,FIND("-",$D$2)+1)) & TEXT(RIGHT($D$2,3)+ROW(D36),"000") -> 1ST-358-037 | E38: 1385/ROLL | F38: =VALUE(LEFT(E38,FIND("/",E38)-1)) -> 1385 | G38: =TRIM(MID(E38,FIND("/",E38)+1,LEN(E38))) -> ROLL | H38: 50 ROLLS, 1 ROLL FREE | I38: Net
A39: 1ST TOOLS TRADING INC. | B39: GARDEN HOSE | C39: PL22090-5 (LT22014-R1)GARDEN HOSE RED 1/2"*90M | D39: =LEFT($D$2,FIND("-",$D$2,FIND("-",$D$2)+1)) & TEXT(RIGHT($D$2,3)+ROW(D37),"000") -> 1ST-358-038 | E39: 800/ROLL | F39: =VALUE(LEFT(E39,FIND("/",E39)-1)) -> 800 | G39: =TRIM(MID(E39,FIND("/",E39)+1,LEN(E39))) -> ROLL | I39: Net
A40: 1ST TOOLS TRADING INC. | B40: GARDEN HOSE | C40: PL22090-6 (LT22014-R2) GARDEN HOSE RED 5/8"*90M | D40: =LEFT($D$2,FIND("-",$D$2,FIND("-",$D$2)+1)) & TEXT(RIGHT($D$2,3)+ROW(D38),"000") -> 1ST-358-039 | E40: 930/ROLL | F40: =VALUE(LEFT(E40,FIND("/",E40)-1)) -> 930 | G40: =TRIM(MID(E40,FIND("/",E40)+1,LEN(E40))) -> ROLL | I40: Net
A41: 1ST TOOLS TRADING INC. | B41: GARDEN HOSE | C41: PL22090-7 (LT22014-R3)GARDEN HOSE RED 3/4"*60M | D41: =LEFT($D$2,FIND("-",$D$2,FIND("-",$D$2)+1)) & TEXT(RIGHT($D$2,3)+ROW(D39),"000") -> 1ST-358-040 | E41: 1030/ROLL | F41: =VALUE(LEFT(E41,FIND("/",E41)-1)) -> 1030 | G41: =TRIM(MID(E41,FIND("/",E41)+1,LEN(E41))) -> ROLL | I41: Net
A42: 1ST TOOLS TRADING INC. | B42: GARDEN HOSE | C42: PL22090-8 (LT22014-R4) GARDEN HOSE RED 1"*60M | D42: =LEFT($D$2,FIND("-",$D$2,FIND("-",$D$2)+1)) & TEXT(RIGHT($D$2,3)+ROW(D40),"000") -> 1ST-358-041 | E42: 1385/ROLL | F42: =VALUE(LEFT(E42,FIND("/",E42)-1)) -> 1385 | G42: =TRIM(MID(E42,FIND("/",E42)+1,LEN(E42))) -> ROLL | I42: Net
A43: 1ST TOOLS TRADING INC. | B43: EXTRA THICK PLASTIC HOSE | C43: PL22091-1 (LT22015-1) EXTRA THICK HOSE 1/4"*150M | D43: =LEFT($D$2,FIND("-",$D$2,FIND("-",$D$2)+1)) & TEXT(RIGHT($D$2,3)+ROW(D41),"000") -> 1ST-358-042 | E43: 750/ROLL | F43: =VALUE(LEFT(E43,FIND("/",E43)-1)) -> 750 | G43: =TRIM(MID(E43,FIND("/",E43)+1,LEN(E43))) -> ROLL | H43: 675/ROLL ASSTD ORDER 20 ROLLS | I43: Net
A44: 1ST TOOLS TRADING INC. | B44: EXTRA THICK PLASTIC HOSE | C44: PL22091-2 (LT22015-2) EXTRA THICK HOSE 5/16"*150M | D44: =LEFT($D$2,FIND("-",$D$2,FIND("-",$D$2)+1)) & TEXT(RIGHT($D$2,3)+ROW(D42),"000") -> 1ST-358-043 | E44: 900/ROLL | F44: =VALUE(LEFT(E44,FIND("/",E44)-1)) -> 900 | G44: =TRIM(MID(E44,FIND("/",E44)+1,LEN(E44))) -> ROLL | H44: 800/ROLL ASSTD ORDER 20 ROLLS | I44: Net
...

Sheet PRODUCT INVENTORY (1st tools)
A1: product_code | B1: supplier_product_code | C1: product_name | D1: avt product name | E1: serial_number | F1: model | G1: category_id | H1: sales_price | I1: unit_id | J1: quantity | K1: remaining_stock | L1: discount
A2: AVT0000001 | B2: =VLOOKUP(C2,'SUPPLIER_ITEMS (1st Tools)'!C2:D199,2,FALSE) -> 1ST-358-046 | C2: PL22092-1 (LT22011-1) CLEAR HOSE 1/8"*300M | D2: ="AV"&RIGHT(C2,LEN(C2)-2) -> AV22092-1 (LT22011-1) CLEAR HOSE 1/8"*300M | G2: CLEAR HOSE | H2: 460 | I2: roll | J2: 0 | K2: 0 | L2: 0
A3: ="AVT"&TEXT(RIGHT(A2,LEN(A2)-3)+1,"0000000") -> AVT0000002 | B3: =VLOOKUP(C3,'SUPPLIER_ITEMS (1st Tools)'!C3:D200,2,FALSE) -> 1ST-358-047 | C3: PL22092-2 (LT22011-2) CLEAR HOSE 3/16"*300M | D3: ="AV"&RIGHT(C3,LEN(C3)-2) -> AV22092-2 (LT22011-2) CLEAR HOSE 3/16"*300M | G3: CLEAR HOSE | H3: 720 | I3: roll | J3: 0 | K3: 0 | L3: 0
A4: ="AVT"&TEXT(RIGHT(A3,LEN(A3)-3)+1,"0000000") -> AVT0000003 | B4: =VLOOKUP(C4,'SUPPLIER_ITEMS (1st Tools)'!C4:D201,2,FALSE) -> 1ST-358-048 | C4: PL22092-3 (LT22011-3) CLEAR HOSE 1/4"*300M | D4: ="AV"&RIGHT(C4,LEN(C4)-2) -> AV22092-3 (LT22011-3) CLEAR HOSE 1/4"*300M | G4: CLEAR HOSE | H4: 900 | I4: roll | J4: 0 | K4: 0 | L4: 0
A5: ="AVT"&TEXT(RIGHT(A4,LEN(A4)-3)+1,"0000000") -> AVT0000004 | B5: =VLOOKUP(C5,'SUPPLIER_ITEMS (1st Tools)'!C5:D202,2,FALSE) -> 1ST-358-049 | C5: PL22092-4 (LT22011-4) CLEAR HOSE 5/16"*300M | D5: ="AV"&RIGHT(C5,LEN(C5)-2) -> AV22092-4 (LT22011-4) CLEAR HOSE 5/16"*300M | G5: CLEAR HOSE | H5: 1650 | I5: roll | J5: 0 | K5: 0 | L5: 0
A6: ="AVT"&TEXT(RIGHT(A5,LEN(A5)-3)+1,"0000000") -> AVT0000005 | B6: =VLOOKUP(C6,'SUPPLIER_ITEMS (1st Tools)'!C6:D203,2,FALSE) -> 1ST-358-050 | C6: PL22092-5 (LT22011-5) CLEAR HOSE 3/8"*150M | D6: ="AV"&RIGHT(C6,LEN(C6)-2) -> AV22092-5 (LT22011-5) CLEAR HOSE 3/8"*150M | G6: CLEAR HOSE | H6: 1100 | I6: roll | J6: 0 | K6: 0 | L6: 0
A7: ="AVT"&TEXT(RIGHT(A6,LEN(A6)-3)+1,"0000000") -> AVT0000006 | B7: =VLOOKUP(C7,'SUPPLIER_ITEMS (1st Tools)'!C7:D204,2,FALSE) -> 1ST-358-051 | C7: PL22092-6 (LT22011-6) CLEAR HOSE 1/2"*150M | D7: ="AV"&RIGHT(C7,LEN(C7)-2) -> AV22092-6 (LT22011-6) CLEAR HOSE 1/2"*150M | G7: CLEAR HOSE | H7: 1680 | I7: roll | J7: 0 | K7: 0 | L7: 0
A8: ="AVT"&TEXT(RIGHT(A7,LEN(A7)-3)+1,"0000000") -> AVT0000007 | B8: =VLOOKUP(C8,'SUPPLIER_ITEMS (1st Tools)'!C8:D205,2,FALSE) -> 1ST-358-052 | C8: PL22092-7 (LT22011-7) CLEAR HOSE 5/8"*150M | D8: ="AV"&RIGHT(C8,LEN(C8)-2) -> AV22092-7 (LT22011-7) CLEAR HOSE 5/8"*150M | G8: CLEAR HOSE | H8: 2260 | I8: roll | J8: 0 | K8: 0 | L8: 0
A9: ="AVT"&TEXT(RIGHT(A8,LEN(A8)-3)+1,"0000000") -> AVT0000008 | B9: =VLOOKUP(C9,'SUPPLIER_ITEMS (1st Tools)'!C9:D206,2,FALSE) -> 1ST-358-034 | C9: PL22090-1 (LT22014-G1) GARDEN HOSE GREEN 1/2"*90M | D9: ="AV"&RIGHT(C9,LEN(C9)-2) -> AV22090-1 (LT22014-G1) GARDEN HOSE GREEN 1/2"*90M | G9: GARDEN HOSE | H9: 1250 | I9: roll | J9: 0 | K9: 0 | L9: 0
A10: ="AVT"&TEXT(RIGHT(A9,LEN(A9)-3)+1,"0000000") -> AVT0000009 | B10: =VLOOKUP(C10,'SUPPLIER_ITEMS (1st Tools)'!C10:D207,2,FALSE) -> 1ST-358-035 | C10: PL22090-2 (LT22014-G2) GARDEN HOSE GREEN 5/8"*90M | D10: ="AV"&RIGHT(C10,LEN(C10)-2) -> AV22090-2 (LT22014-G2) GARDEN HOSE GREEN 5/8"*90M | G10: GARDEN HOSE | H10: 1450 | I10: roll | J10: 0 | K10: 0 | L10: 0
A11: ="AVT"&TEXT(RIGHT(A10,LEN(A10)-3)+1,"0000000") -> AVT0000010 | B11: =VLOOKUP(C11,'SUPPLIER_ITEMS (1st Tools)'!C11:D208,2,FALSE) -> 1ST-358-036 | C11: PL22090-3 (LT22014-G3)GARDEN HOSE GREEN 3/4"*60M | D11: ="AV"&RIGHT(C11,LEN(C11)-2) -> AV22090-3 (LT22014-G3)GARDEN HOSE GREEN 3/4"*60M | G11: GARDEN HOSE | H11: 1650 | I11: roll | J11: 0 | K11: 0 | L11: 0
A12: ="AVT"&TEXT(RIGHT(A11,LEN(A11)-3)+1,"0000000") -> AVT0000011 | B12: =VLOOKUP(C12,'SUPPLIER_ITEMS (1st Tools)'!C12:D209,2,FALSE) -> 1ST-358-037 | C12: PL22090-4 (LT22014-G4) GARDEN HOSE GREEN 1"*60M | D12: ="AV"&RIGHT(C12,LEN(C12)-2) -> AV22090-4 (LT22014-G4) GARDEN HOSE GREEN 1"*60M | G12: GARDEN HOSE | H12: 2250 | I12: roll | J12: 0 | K12: 0 | L12: 0
A13: ="AVT"&TEXT(RIGHT(A12,LEN(A12)-3)+1,"0000000") -> AVT0000012 | B13: =VLOOKUP(C13,'SUPPLIER_ITEMS (1st Tools)'!C13:D210,2,FALSE) -> 1ST-358-038 | C13: PL22090-5 (LT22014-R1)GARDEN HOSE RED 1/2"*90M | D13: ="AV"&RIGHT(C13,LEN(C13)-2) -> AV22090-5 (LT22014-R1)GARDEN HOSE RED 1/2"*90M | G13: GARDEN HOSE | H13: 1250 | I13: roll | J13: 0 | K13: 0 | L13: 0
A14: ="AVT"&TEXT(RIGHT(A13,LEN(A13)-3)+1,"0000000") -> AVT0000013 | B14: =VLOOKUP(C14,'SUPPLIER_ITEMS (1st Tools)'!C14:D211,2,FALSE) -> 1ST-358-039 | C14: PL22090-6 (LT22014-R2) GARDEN HOSE RED 5/8"*90M | D14: ="AV"&RIGHT(C14,LEN(C14)-2) -> AV22090-6 (LT22014-R2) GARDEN HOSE RED 5/8"*90M | G14: GARDEN HOSE | H14: 1450 | I14: roll | J14: 0 | K14: 0 | L14: 0
... A34: ="AVT"&TEXT(RIGHT(A33,LEN(A33)-3)+1,"0000000") -> AVT0000033 | B34: =VLOOKUP(C34,'SUPPLIER_ITEMS (1st Tools)'!C34:D231,2,FALSE) -> 1ST-358-085 | C34: PL22140 (PLMA001) POLOLOCK JETMATIC PUMP | D34: ="AV"&RIGHT(C34,LEN(C34)-2) -> AV22140 (PLMA001) POLOLOCK JETMATIC PUMP | G34: JETMATIC PUMP | H34: 2500 | I34: pc/ctn | J34: 0 | K34: 0 | L34: 0
